<?xml version="1.0"?>
<robot name="bot">

  <!-- Base link -->
  <link name="base_link">
    <gazebo>
      <plugin name="gazebo_ros_control" filename="libgazebo_ros_control.so">
        <robotNamespace>/</robotNamespace>
        <controlPeriod>0.001</controlPeriod>
        <robotParam>robot_description</robotParam>
      </plugin>
    </gazebo>
  </link>

  <!-- Differential Drive Plugin -->
  <gazebo>
    <plugin name="differential_drive_controller" filename="libgazebo_ros_diff_drive.so">
      <ros>
        <namespace>/</namespace>
      </ros>
      <left_joint>left_wheel_joint</left_joint>
      <right_joint>right_wheel_joint</right_joint>
      <wheel_separation>0.35</wheel_separation>  <!-- 0.175*2 -->
      <wheel_diameter>0.1</wheel_diameter>
      <max_wheel_torque>20</max_wheel_torque>
      <max_wheel_acceleration>1.0</max_wheel_acceleration>
      <command_topic>cmd_vel</command_topic>
      <odometry_topic>odom</odometry_topic>
      <odometry_frame>odom</odometry_frame>
      <robot_base_frame>base_link</robot_base_frame>
      <publish_odom>true</publish_odom>
      <publish_odom_tf>true</publish_odom_tf>
      <publish_wheel_tf>false</publish_wheel_tf>
    </plugin>
  </gazebo>

  <!-- Wheel Transmissions -->
  <transmission name="left_wheel_trans">
    <type>transmission_interface/SimpleTransmission</type>
    <joint name="left_wheel_joint">
      <hardwareInterface>hardware_interface/VelocityJointInterface</hardwareInterface>
    </joint>
    <actuator name="left_wheel_motor">
      <hardwareInterface>hardware_interface/VelocityJointInterface</hardwareInterface>
      <mechanicalReduction>1</mechanicalReduction>
    </actuator>
  </transmission>

  <transmission name="right_wheel_trans">
    <type>transmission_interface/SimpleTransmission</type>
    <joint name="right_wheel_joint">
      <hardwareInterface>hardware_interface/VelocityJointInterface</hardwareInterface>
    </joint>
    <actuator name="right_wheel_motor">
      <hardwareInterface>hardware_interface/VelocityJointInterface</hardwareInterface>
      <mechanicalReduction>1</mechanicalReduction>
    </actuator>
  </transmission>

  <!-- Chassis -->
  <joint name="chassis_joint" type="fixed">
    <parent link="base_link"/>
    <child link="chassis"/>
    <origin xyz="-0.1 0 0"/>
  </joint>

  <link name="chassis">
    <visual>
      <origin xyz="0.15 0 0.075"/>
      <geometry>
        <box size="0.3 0.3 0.15"/>
      </geometry>
      <material name="white"/>
    </visual>
    <collision>
      <origin xyz="0.15 0 0.075"/>
      <geometry>
        <box size="0.3 0.3 0.15"/>
      </geometry>
    </collision>
    <inertial>
      <origin xyz="0.15 0 0.075" rpy="0 0 0"/>
      <mass value="0.5"/>
      <inertia ixx="0.003125" ixy="0" ixz="0"
               iyy="0.003125" iyz="0"
               izz="0.0075"/>
    </inertial>
  </link>

  <!-- Left Wheel -->
  <joint name="left_wheel_joint" type="continuous">
    <parent link="base_link"/>
    <child link="left_wheel"/>
    <origin xyz="0 0.175 0" rpy="-1.57079632679 0 0" />
    <axis xyz="0 0 1"/>
  </joint>

  <link name="left_wheel">
    <visual>
      <geometry>
        <cylinder radius="0.05" length="0.04"/>
      </geometry>
      <material name="blue"/>
    </visual>
    <collision>
      <geometry>
        <cylinder radius="0.05" length="0.04"/>
      </geometry>
    </collision>
    <inertial>
      <origin xyz="0 0 0" rpy="0 0 0"/>
      <mass value="0.1"/>
      <inertia ixx="5.41666666667e-05" ixy="0" ixz="0"
               iyy="5.41666666667e-05" iyz="0"
               izz="1.25e-04"/>
    </inertial>
  </link>

  <!-- Right Wheel -->
  <joint name="right_wheel_joint" type="continuous">
    <parent link="base_link"/>
    <child link="right_wheel"/>
    <origin xyz="0 -0.175 0" rpy="1.57079632679 0 0" />
    <axis xyz="0 0 -1"/>
  </joint>

  <link name="right_wheel">
    <visual>
      <geometry>
        <cylinder radius="0.05" length="0.04"/>
      </geometry>
      <material name="blue"/>
    </visual>
    <collision>
      <geometry>
        <cylinder radius="0.05" length="0.04"/>
      </geometry>
    </collision>
    <inertial>
      <origin xyz="0 0 0" rpy="0 0 0"/>
      <mass value="0.1"/>
      <inertia ixx="5.41666666667e-05" ixy="0" ixz="0"
               iyy="5.41666666667e-05" iyz="0"
               izz="1.25e-04"/>
    </inertial>
  </link>

  <!-- Caster Wheel -->
  <joint name="caster_wheel_joint" type="fixed">
    <parent link="chassis"/>
    <child link="caster_wheel"/>
    <origin xyz="0.24 0 0"/>
  </joint>

  <link name="caster_wheel">
    <visual>
      <geometry>
        <sphere radius="0.05"/>
      </geometry>
      <material name="black"/>
    </visual>
    <collision>
      <geometry>
        <sphere radius="0.05"/>
      </geometry>
    </collision>
    <inertial>
      <origin xyz="0 0 0" rpy="0 0 0"/>
      <mass value="0.1"/>
      <inertia ixx="2e-04" ixy="0" ixz="0"
               iyy="2e-04" iyz="0"
               izz="2e-04"/>
    </inertial>
  </link>

    <gazebo reference="caster_wheel">
        <mu1>0.0</mu1>  <!-- Friction coefficient in direction of motion -->
        <mu2>0.0</mu2>  <!-- Friction coefficient perpendicular to motion -->
        <kp>1000000.0</kp>  <!-- Contact stiffness -->
        <kd>1.0</kd>      <!-- Contact damping -->
        <material>Gazebo/Black</material>
        <turnGravityOff>false</turnGravityOff>
    </gazebo>

  <!-- LIDAR Sensor -->
<link name="lidar_link">
  <visual>
    <geometry>
      <cylinder length="0.05" radius="0.05"/>
    </geometry>
    <material name="red">
      <color rgba="1 0 0 0.5"/>
    </material>
  </visual>
  <collision>
    <geometry>
      <cylinder length="0.05" radius="0.05"/>
    </geometry>
  </collision>
  <inertial>
    <mass value="0.1"/>
    <inertia ixx="0.001" ixy="0" ixz="0" iyy="0.001" iyz="0" izz="0.001"/>
  </inertial>
</link>

<joint name="lidar_joint" type="fixed">
  <parent link="base_link"/> <!-- Attach to your base -->
  <child link="lidar_link"/>
  <origin xyz="0.1 0 0.2" rpy="0 0 0"/> <!-- Adjust position -->
</joint>

<!-- Gazebo LIDAR Plugin -->
<gazebo reference="lidar_link">
  <sensor name="lidar_sensor" type="ray">
    <pose>0 0 0 0 0 0</pose>
    <visualize>true</visualize> <!-- Set to false for better performance -->
    <update_rate>10</update_rate>
    <ray>
      <scan>
        <horizontal>
          <samples>360</samples> <!-- Resolution -->
          <resolution>1.0</resolution>
          <min_angle>0.0</min_angle>
          <max_angle>6.28319</max_angle> <!-- 2π radians = 360° -->
        </horizontal>
      </scan>
      <range>
        <min>0.12</min>
        <max>10.0</max> <!-- Range in meters -->
        <resolution>0.01</resolution>
      </range>
      <noise>
        <type>gaussian</type>
        <mean>0.0</mean>
        <stddev>0.01</stddev>
      </noise>
    </ray>
    <plugin name="lidar_controller" filename="libgazebo_ros_ray_sensor.so">
      <ros>
        <namespace>/</namespace>
        <remapping>~/out:=scan</remapping> <!-- Output topic -->
      </ros>
      <frame_name>lidar_link</frame_name>
      <radiation_type>infrared</radiation_type> <!-- Or 'laser' -->
    </plugin>
  </sensor>
</gazebo>

<!-- Camera Link - Made more visible -->
<link name="camera_link">
  <visual>
    <geometry>
      <box size="0.08 0.06 0.06"/>  <!-- Increased size -->
    </geometry>
    <material name="bright_green">
      <color rgba="0 1 0 1"/>  <!-- Bright green color -->
    </material>
  </visual>
  <collision>
    <geometry>
      <box size="0.05 0.03 0.03"/>
    </geometry>
  </collision>
  <inertial>
    <mass value="0.05"/>
    <inertia ixx="0.00001" ixy="0" ixz="0" iyy="0.00001" iyz="0" izz="0.00001"/>
  </inertial>
</link>

<!-- Camera Joint - Slightly adjusted position -->
<joint name="camera_joint" type="fixed">
  <parent link="chassis"/>
  <child link="camera_link"/>
  <origin xyz="0.42 0 0.12" rpy="0 -0.2618 0"/>  <!-- 22cm forward, 12cm up -->
</joint>

<!-- Camera Plugin - Simplified and reliable -->
<gazebo reference="camera_link">
  <sensor name="front_camera" type="camera">
    <always_on>true</always_on>
    <update_rate>30</update_rate>
    <visualize>true</visualize>  <!-- Shows frustum in Gazebo -->
    <camera>
      <horizontal_fov>1.047</horizontal_fov>  <!-- 60° FOV -->
      <image>
        <width>640</width>
        <height>480</height>
        <format>R8G8B8</format>
      </image>
      <clip>
        <near>0.05</near>  <!-- Reduced from 0.1 for better close-up viewing -->
        <far>50</far>
      </clip>
    </camera>
    <plugin name="camera_plugin" filename="libgazebo_ros_camera.so">
      <ros>
        <namespace>/camera</namespace>
      </ros>
      <camera_name>front_camera</camera_name>
      <frame_name>camera_link</frame_name>
      <topic_name>image_raw</topic_name>
    </plugin>
  </sensor>
</gazebo>

</robot>